<?xml version="1.0" encoding="utf-8"?>
<!-- This URDF was automatically created by SolidWorks to URDF Exporter! Originally created by Stephen Brawner (brawner@gmail.com) 
     Commit Version: 1.6.0-1-g15f4949  Build Version: 1.6.7594.29634
     For more information, please see http://wiki.ros.org/sw_urdf_exporter -->
<robot
  name="farm_bot_urdf">
  <link
    name="base_link">
    <inertial>
      <origin
        xyz="-0.00413302315404124 0.00666211969872622 -8.65044041209199E-11"
        rpy="0 0 0" />
      <mass
        value="0.365211098963578" />
      <inertia
        ixx="0.000587851832472422"
        ixy="-2.5088865580259E-06"
        ixz="-1.85797674499311E-11"
        iyy="0.00275979469789039"
        iyz="-3.06654702051706E-13"
        izz="0.00220629413672777" />
    </inertial>
    <visual>
      <origin
        xyz="0 0 0"
        rpy="0 0 0" />
      <geometry>
        <mesh
          filename="package://farm_bot/meshes/base_link.STL" />
      </geometry>
      <material
        name="">
        <color
          rgba="0.792156862745098 0.819607843137255 0.933333333333333 1" />
      </material>
    </visual>
    <collision>
      <origin
        xyz="0 0 0"
        rpy="0 0 0" />
      <geometry>
        <mesh
          filename="package://farm_bot/meshes/base_link.STL" />
      </geometry>
    </collision>
  </link>
  <link
    name="piston front">
    <inertial>
      <origin
        xyz="1.38777878078145E-17 3.43680040246323E-17 0.0304789370624094"
        rpy="0 0 0" />
      <mass
        value="0.0492496861306418" />
      <inertia
        ixx="3.61940839038542E-05"
        ixy="-6.38007239207329E-23"
        ixz="-3.17637355220363E-21"
        iyy="3.61940839038542E-05"
        iyz="-5.03314590811531E-21"
        izz="5.26782397919921E-06" />
    </inertial>
    <visual>
      <origin
        xyz="0 0 0"
        rpy="0 0 0" />
      <geometry>
        <mesh
          filename="package://farm_bot/meshes/piston front.STL" />
      </geometry>
      <material
        name="">
        <color
          rgba="0.792156862745098 0.819607843137255 0.933333333333333 1" />
      </material>
    </visual>
    <collision>
      <origin
        xyz="0 0 0"
        rpy="0 0 0" />
      <geometry>
        <mesh
          filename="package://farm_bot/meshes/piston front.STL" />
      </geometry>
    </collision>
  </link>
  <joint
    name="piston1"
    type="prismatic">
    <origin
      xyz="-0.043301 0 0.025"
      rpy="-3.1416 -0.5236 3.1416" />
    <parent
      link="base_link" />
    <child
      link="piston front" />
    <axis
      xyz="0 0 1" />
    <limit
      lower="-0.06"
      upper="0"
      effort="0"
      velocity="0" />
  </joint>
  <link
    name="piston rear">
    <inertial>
      <origin
        xyz="6.93889390390723E-18 -1.85814245279061E-17 0.0304789370624093"
        rpy="0 0 0" />
      <mass
        value="0.0492496861306418" />
      <inertia
        ixx="3.61940839038542E-05"
        ixy="2.45808401609207E-24"
        ixz="-1.6940658945086E-21"
        iyy="3.61940839038542E-05"
        iyz="-2.46741021972222E-21"
        izz="5.2678239791992E-06" />
    </inertial>
    <visual>
      <origin
        xyz="0 0 0"
        rpy="0 0 0" />
      <geometry>
        <mesh
          filename="package://farm_bot/meshes/piston rear.STL" />
      </geometry>
      <material
        name="">
        <color
          rgba="0.792156862745098 0.819607843137255 0.933333333333333 1" />
      </material>
    </visual>
    <collision>
      <origin
        xyz="0 0 0"
        rpy="0 0 0" />
      <geometry>
        <mesh
          filename="package://farm_bot/meshes/piston rear.STL" />
      </geometry>
    </collision>
  </link>
  <joint
    name="piston2"
    type="prismatic">
    <origin
      xyz="0.043301 0 0.025"
      rpy="3.1416 0.5236 3.1416" />
    <parent
      link="base_link" />
    <child
      link="piston rear" />
    <axis
      xyz="0 0 1" />
    <limit
      lower="-0.06"
      upper="0"
      effort="0"
      velocity="0" />
  </joint>
  <link
    name="wheel right front">
    <inertial>
      <origin
        xyz="-0.0481728034412505 0 1.38777878078145E-17"
        rpy="0 0 0" />
      <mass
        value="0.170342906048753" />
      <inertia
        ixx="0.000197594540802262"
        ixy="5.82461381845058E-21"
        ixz="4.09496689598892E-21"
        iyy="0.000115040014294501"
        iyz="-1.35525271560688E-20"
        izz="0.000115040014294501" />
    </inertial>
    <visual>
      <origin
        xyz="0 0 0"
        rpy="0 0 0" />
      <geometry>
        <mesh
          filename="package://farm_bot/meshes/wheel right front.STL" />
      </geometry>
      <material
        name="">
        <color
          rgba="0.792156862745098 0.819607843137255 0.933333333333333 1" />
      </material>
    </visual>
    <collision>
      <origin
        xyz="0 0 0"
        rpy="0 0 0" />
      <geometry>
        <mesh
          filename="package://farm_bot/meshes/wheel right front.STL" />
      </geometry>
    </collision>
  </link>
  <joint
    name="wheel_right_front"
    type="continuous">
    <origin
      xyz="-0.1 -0.05 0.03"
      rpy="-2.0772 0 1.5708" />
    <parent
      link="base_link" />
    <child
      link="wheel right front" />
    <axis
      xyz="1 0 0" />
    <limit
      lower="0"
      upper="3.14"
      effort="40"
      velocity="78.4" />
  </joint>
  <link
    name="wheel left front">
    <inertial>
      <origin
        xyz="-0.0481728034412505 0 6.93889390390723E-18"
        rpy="0 0 0" />
      <mass
        value="0.170342906048753" />
      <inertia
        ixx="0.000197594540802262"
        ixy="3.460241947874E-21"
        ixz="-8.60047549874402E-21"
        iyy="0.000115040014294501"
        iyz="0"
        izz="0.000115040014294501" />
    </inertial>
    <visual>
      <origin
        xyz="0 0 0"
        rpy="0 0 0" />
      <geometry>
        <mesh
          filename="package://farm_bot/meshes/wheel left front.STL" />
      </geometry>
      <material
        name="">
        <color
          rgba="0.792156862745098 0.819607843137255 0.933333333333333 1" />
      </material>
    </visual>
    <collision>
      <origin
        xyz="0 0 0"
        rpy="0 0 0" />
      <geometry>
        <mesh
          filename="package://farm_bot/meshes/wheel left front.STL" />
      </geometry>
    </collision>
  </link>
  <joint
    name="wheel_left_front"
    type="continuous">
    <origin
      xyz="-0.1 0.05 0.03"
      rpy="2.8045 0 -1.5708" />
    <parent
      link="base_link" />
    <child
      link="wheel left front" />
    <axis
      xyz="-1 0 0" />
    <limit
      lower="0"
      upper="3.14"
      effort="40"
      velocity="78.4" />
  </joint>
  <link
    name="wheel left rear">
    <inertial>
      <origin
        xyz="-0.0481728034412505 0 2.08166817117217E-17"
        rpy="0 0 0" />
      <mass
        value="0.170342906048753" />
      <inertia
        ixx="0.000197594540802262"
        ixy="1.01865426869992E-21"
        ixz="1.18042317166485E-20"
        iyy="0.000115040014294501"
        iyz="5.0821976835258E-21"
        izz="0.000115040014294501" />
    </inertial>
    <visual>
      <origin
        xyz="0 0 0"
        rpy="0 0 0" />
      <geometry>
        <mesh
          filename="package://farm_bot/meshes/wheel left rear.STL" />
      </geometry>
      <material
        name="">
        <color
          rgba="0.792156862745098 0.819607843137255 0.933333333333333 1" />
      </material>
    </visual>
    <collision>
      <origin
        xyz="0 0 0"
        rpy="0 0 0" />
      <geometry>
        <mesh
          filename="package://farm_bot/meshes/wheel left rear.STL" />
      </geometry>
    </collision>
  </link>
  <joint
    name="wheel_left_rear"
    type="continuous">
    <origin
      xyz="0.1 0.05 0.03"
      rpy="-3.0288 0 -1.5708" />
    <parent
      link="base_link" />
    <child
      link="wheel left rear" />
    <axis
      xyz="-1 0 0" />
    <limit
      lower="0"
      upper="3.14"
      effort="40"
      velocity="78.4" />
  </joint>
  <link
    name="wheel right rear">
    <inertial>
      <origin
        xyz="-0.0481728034412505 -1.38777878078145E-17 5.55111512312578E-17"
        rpy="0 0 0" />
      <mass
        value="0.170342906048753" />
      <inertia
        ixx="0.000197594540802262"
        ixy="1.33989645938052E-20"
        ixz="2.19619835461011E-22"
        iyy="0.000115040014294501"
        iyz="-3.72694496791892E-20"
        izz="0.000115040014294501" />
    </inertial>
    <visual>
      <origin
        xyz="0 0 0"
        rpy="0 0 0" />
      <geometry>
        <mesh
          filename="package://farm_bot/meshes/wheel right rear.STL" />
      </geometry>
      <material
        name="">
        <color
          rgba="0.792156862745098 0.819607843137255 0.933333333333333 1" />
      </material>
    </visual>
    <collision>
      <origin
        xyz="0 0 0"
        rpy="0 0 0" />
      <geometry>
        <mesh
          filename="package://farm_bot/meshes/wheel right rear.STL" />
      </geometry>
    </collision>
  </link>
  <joint
    name="wheel_right_rear"
    type="continuous">
    <origin
      xyz="0.1 -0.05 0.03"
      rpy="-2.0959 0 1.5708" />
    <parent
      link="base_link" />
    <child
      link="wheel right rear" />
    <axis
      xyz="1 0 0" />
    <limit
      lower="0"
      upper="3.14"
      effort="40"
      velocity="78.4" />
  </joint>
   <joint name="gps_joint" type="fixed">
  <origin xyz="0 0 0"/>
  <parent link="base_link"/>
  <child link="gps_link"/>
</joint>

<link name="gps_link">
  <inertial>
    <mass value="0.001" />
    <origin xyz="0 0 0" rpy="0 0 0" />
    <inertia ixx="0.000000017" ixy="0" ixz="0" iyy="0.000000017" iyz="0" izz="0.000000017" />
  </inertial>
  <visual>
    <origin xyz="0 0 0" rpy="0 0 0" />
    <geometry>
      <box size="0.01 0.01 0.01" />          
    </geometry>
  </visual>
  <collision>
    <origin xyz="0 0 0" rpy="0 0 0" />
    <geometry>
      <box size="0.01 0.01 0.01" />
    </geometry>
  </collision>
</link>


  <joint name="imu_joint" type="fixed">
    <axis xyz="0 0 0"/> <!-- 0 1 0 -->
    <origin xyz="0 0 -0.01"/>
    <parent link="base_link"/>
    <child link="imu_link"/>
  </joint>


<link name="imu_link">
   <inertial>
        <mass value="0.5" />
        <origin xyz="0 0 0" />
        <inertia ixx="0.0" ixy="0.0" ixz="0.0"
                 iyy="0.0" iyz="0.0" 
                 izz="0.0" />
    </inertial>    
        <visual>
        <origin xyz="0 0 0" rpy="0 0 0" />
        <geometry>
           <box size = "0.01 0.01 0.01"/>
        </geometry>
        </visual>
    <collision>         
        <geometry>
            <box size = "0.01 0.01 0.01"/> 
        </geometry>
    </collision>     
    </link>
  <!--          Gazebo related Part                -->
  <gazebo>
    <plugin name="gazebo_ros_control" filename="libgazebo_ros_control.so">
      <robotNamespace>/MYROBOT</robotNamespace>
    </plugin>
    <plugin name="gps" filename="libhector_gazebo_ros_gps.so">  
      <updateRate>10.0</updateRate>  
      <topicName>sensor_msgs/NavSatFix</topicName>  
      <gaussianNoise>0.0 0.0 0.0</gaussianNoise>  
      <offset>0 0 0</offset>  
      <velocityGaussianNoise>0 0 0</velocityGaussianNoise>  
      <frameId>base_link</frameId>  
    </plugin>
    <plugin name="imu_plugin" filename="libgazebo_ros_imu.so">
      <alwaysOn>true</alwaysOn>
      <bodyName>imu_link</bodyName> 
      <topicName>imu</topicName>
      <serviceName>imu_service</serviceName>
      <gaussianNoise>0.0</gaussianNoise>
      <updateRate>20.0</updateRate>
    </plugin>
  </gazebo>   
  <!--          Transmissions           -->
  <transmission name="wheel_r_trans">
    <type>transmission_interface/SimpleTransmission</type>
    <actuator name="motor1">
      <mechanicalReduction>1</mechanicalReduction>
    </actuator>
    <joint name="wheel_right_front">
      <hardwareInterface>hardware_interface/EffortJointInterface</hardwareInterface>
    </joint>
  </transmission>
  
  <transmission name="wheel_l_trans">
    <type>transmission_interface/SimpleTransmission</type>
    <actuator name="motor2">
      <mechanicalReduction>1</mechanicalReduction>
    </actuator>
    <joint name="wheel_left_front">
      <hardwareInterface>hardware_interface/EffortJointInterface</hardwareInterface>
    </joint>
  </transmission>
  
  <transmission name="wheel_l_trans">
    <type>transmission_interface/SimpleTransmission</type>
    <actuator name="motor2">
      <mechanicalReduction>1</mechanicalReduction>
    </actuator>
    <joint name="wheel_left_rear">
      <hardwareInterface>hardware_interface/EffortJointInterface</hardwareInterface>
    </joint>
  </transmission>
  
  <transmission name="wheel_r_trans">
    <type>transmission_interface/SimpleTransmission</type>
    <actuator name="motor1">
      <mechanicalReduction>1</mechanicalReduction>
    </actuator>
    <joint name="wheel_right_rear">
      <hardwareInterface>hardware_interface/EffortJointInterface</hardwareInterface>
    </joint>
  </transmission>       
  </robot>
